Workbook

Sheet Export Summary
B3: This document was exported from Numbers. Each table was converted to an Excel worksheet. All other objects on each Numbers sheet were placed on separate worksheets. Please be aware that formula calculations may differ in Excel.
B7: Numbers Sheet Name | C7: Numbers Table Name | D7: Excel Worksheet Name
B9: Mamdoudé
C10: Recipe | D10: Mamdoudé - Recipe
C11: Sample Recipe | D11: Mamdoudé - Sample Recipe
C12: “All Drawings from the Sheet” | D12: Mamdoudé - Drawings
B13: Bl Sayniyé
C14: Sample Recipe | D14: Bl Sayniyé - Sample Recipe
C15: Recipe | D15: Bl Sayniyé - Recipe
C16: “All Drawings from the Sheet” | D16: Bl Sayniyé - Drawings
B17: Feta Kebbé
C18: Sample Recipe | D18: Feta Kebbé - Sample Recipe
C19: Recipe | D19: Feta Kebbé - Recipe
C20: “All Drawings from the Sheet” | D20: Feta Kebbé - Drawings
B21: Onion & Pine
C22: Sample Recipe | D22: Onion & Pine - Sample Recipe
C23: Recipe | D23: Onion & Pine - Recipe
C24: “All Drawings from the Sheet” | D24: Onion & Pine - Drawings
B25: Nayyé
C26: Sample Recipe | D26: Nayyé - Sample Recipe
C27: Recipe | D27: Nayyé - Recipe
C28: “All Drawings from the Sheet” | D28: Nayyé - Drawings
B29: Hommos Kebbé
C30: Sample Recipe | D30: Hommos Kebbé - Sample Recipe
C31: Recipe | D31: Hommos Kebbé - Recipe
C32: “All Drawings from the Sheet” | D32: Hommos Kebbé - Drawings
B33: Bou Emné
C34: Sample Recipe | D34: Bou Emné - Sample Recipe
C35: Recipe | D35: Bou Emné - Recipe
C36: “All Drawings from the Sheet” | D36: Bou Emné - Drawings
B37: La'tine
C38: Sample Recipe | D38: La'tine - Sample Recipe
C39: Recipe | D39: La'tine - Recipe
C40: “All Drawings from the Sheet” | D40: La'tine - Drawings
B41: Spiced Butter E'rass
C42: Sample Recipe | D42: Spiced Butter E'rass - Sample R
C43: Recipe | D43: Spiced Butter E'rass - Recipe
C44: “All Drawings from the Sheet” | D44: Spiced Butter E'rass - Drawings
B45: Kabkoub Acovado
C46: Sample Recipe | D46: Kabkoub Acovado - Sample Recipe
...

Sheet Mamdoudé - Recipe
A1: Ingredient | B1: Regular | E1: Small
A2: Meat | B2: 300 | C2: g | D2: =IF(C2="oz","ozm",IF(C2="tbsp","tbs",IF(C2="fl oz","oz",IF(C2="L","l",IF(C2="mL","ml",IF(C2="lb","lbm",IF(C2="----","F",C2))))))) -> g | E2: =IF(AND(D2="F",G2="F"),B2,CONVERT(B2,D2,G2))*'Mamdoudé - Sample Recipe'!$C$2/'Mamdoudé - Sample Recipe'!$B$2 -> 159 | F2: g | G2: =IF(F2="oz","ozm",IF(F2="tbsp","tbs",IF(F2="fl oz","oz",IF(F2="L","l",IF(F2="mL","ml",IF(F2="lb","lbm",IF(F2="----","F",F2))))))) -> g
A3: Borghol | B3: 150 | C3: g | D3: =IF(C3="oz","ozm",IF(C3="tbsp","tbs",IF(C3="fl oz","oz",IF(C3="L","l",IF(C3="mL","ml",IF(C3="lb","lbm",IF(C3="----","F",C3))))))) -> g | E3: =IF(AND(D3="F",G3="F"),B3,CONVERT(B3,D3,G3))*'Mamdoudé - Sample Recipe'!$C$2/'Mamdoudé - Sample Recipe'!$B$2 -> 79.5 | F3: g | G3: =IF(F3="oz","ozm",IF(F3="tbsp","tbs",IF(F3="fl oz","oz",IF(F3="L","l",IF(F3="mL","ml",IF(F3="lb","lbm",IF(F3="----","F",F3))))))) -> g
A4: Olive Oil | B4: 120 | C4: mL | D4: =IF(C4="oz","ozm",IF(C4="tbsp","tbs",IF(C4="fl oz","oz",IF(C4="L","l",IF(C4="mL","ml",IF(C4="lb","lbm",IF(C4="----","F",C4))))))) -> ml | E4: =IF(AND(D4="F",G4="F"),B4,CONVERT(B4,D4,G4))*'Mamdoudé - Sample Recipe'!$C$2/'Mamdoudé - Sample Recipe'!$B$2 -> 63.6 | F4: mL | G4: =IF(F4="oz","ozm",IF(F4="tbsp","tbs",IF(F4="fl oz","oz",IF(F4="L","l",IF(F4="mL","ml",IF(F4="lb","lbm",IF(F4="----","F",F4))))))) -> ml
A5: Salt | B5: 2 | C5: tsp | D5: =IF(C5="oz","ozm",IF(C5="tbsp","tbs",IF(C5="fl oz","oz",IF(C5="L","l",IF(C5="mL","ml",IF(C5="lb","lbm",IF(C5="----","F",C5))))))) -> tsp | E5: =IF(AND(D5="F",G5="F"),B5,CONVERT(B5,D5,G5))*'Mamdoudé - Sample Recipe'!$C$2/'Mamdoudé - Sample Recipe'!$B$2 -> 1.06 | F5: tsp | G5: =IF(F5="oz","ozm",IF(F5="tbsp","tbs",IF(F5="fl oz","oz",IF(F5="L","l",IF(F5="mL","ml",IF(F5="lb","lbm",IF(F5="----","F",F5))))))) -> tsp
A6: Ground Pepper | B6: 1 | C6: tsp | D6: =IF(C6="oz","ozm",IF(C6="tbsp","tbs",IF(C6="fl oz","oz",IF(C6="L","l",IF(C6="mL","ml",IF(C6="lb","lbm",IF(C6="----","F",C6))))))) -> tsp | E6: =IF(AND(D6="F",G6="F"),B6,CONVERT(B6,D6,G6))*'Mamdoudé - Sample Recipe'!$C$2/'Mamdoudé - Sample Recipe'!$B$2 -> 0.53 | F6: tsp | G6: =IF(F6="oz","ozm",IF(F6="tbsp","tbs",IF(F6="fl oz","oz",IF(F6="L","l",IF(F6="mL","ml",IF(F6="lb","lbm",IF(F6="----","F",F6))))))) -> tsp

Sheet Mamdoudé - Sample Recipe
B1: Prepared for | C1: Prepared for
B2: 10 | C2: 5.3

Sheet Mamdoudé - Drawings

Sheet Bl Sayniyé - Sample Recipe
A1: Sample Recipe
B2: Recipe serves | C2: Prepared for
B3: 10 | C3: 5.3

Sheet Bl Sayniyé - Recipe
A1: Ingredient | B1: Regular | E1: Small
A2: Meat | B2: 550 | C2: g | D2: =IF(C2="oz","ozm",IF(C2="tbsp","tbs",IF(C2="fl oz","oz",IF(C2="L","l",IF(C2="mL","ml",IF(C2="lb","lbm",IF(C2="----","F",C2))))))) -> g | E2: =IF(AND(D2="F",G2="F"),B2,CONVERT(B2,D2,G2))*'Bl Sayniyé - Sample Recipe'!$C$3/'Bl Sayniyé - Sample Recipe'!$B$3 -> 291.5 | F2: g | G2: =IF(F2="oz","ozm",IF(F2="tbsp","tbs",IF(F2="fl oz","oz",IF(F2="L","l",IF(F2="mL","ml",IF(F2="lb","lbm",IF(F2="----","F",F2))))))) -> g
A3: Borghol | B3: 250 | C3: g | D3: =IF(C3="oz","ozm",IF(C3="tbsp","tbs",IF(C3="fl oz","oz",IF(C3="L","l",IF(C3="mL","ml",IF(C3="lb","lbm",IF(C3="----","F",C3))))))) -> g | E3: =IF(AND(D3="F",G3="F"),B3,CONVERT(B3,D3,G3))*'Bl Sayniyé - Sample Recipe'!$C$3/'Bl Sayniyé - Sample Recipe'!$B$3 -> 132.5 | F3: g | G3: =IF(F3="oz","ozm",IF(F3="tbsp","tbs",IF(F3="fl oz","oz",IF(F3="L","l",IF(F3="mL","ml",IF(F3="lb","lbm",IF(F3="----","F",F3))))))) -> g
A4: Pine nuts | B4: 18 | C4: g | D4: =IF(C4="oz","ozm",IF(C4="tbsp","tbs",IF(C4="fl oz","oz",IF(C4="L","l",IF(C4="mL","ml",IF(C4="lb","lbm",IF(C4="----","F",C4))))))) -> g | E4: =IF(AND(D4="F",G4="F"),B4,CONVERT(B4,D4,G4))*'Bl Sayniyé - Sample Recipe'!$C$3/'Bl Sayniyé - Sample Recipe'!$B$3 -> 9.54 | F4: g | G4: =IF(F4="oz","ozm",IF(F4="tbsp","tbs",IF(F4="fl oz","oz",IF(F4="L","l",IF(F4="mL","ml",IF(F4="lb","lbm",IF(F4="----","F",F4))))))) -> g
A5: Onion | B5: 160 | C5: g | D5: =IF(C5="oz","ozm",IF(C5="tbsp","tbs",IF(C5="fl oz","oz",IF(C5="L","l",IF(C5="mL","ml",IF(C5="lb","lbm",IF(C5="----","F",C5))))))) -> g | E5: =IF(AND(D5="F",G5="F"),B5,CONVERT(B5,D5,G5))*'Bl Sayniyé - Sample Recipe'!$C$3/'Bl Sayniyé - Sample Recipe'!$B$3 -> 84.8 | F5: g | G5: =IF(F5="oz","ozm",IF(F5="tbsp","tbs",IF(F5="fl oz","oz",IF(F5="L","l",IF(F5="mL","ml",IF(F5="lb","lbm",IF(F5="----","F",F5))))))) -> g
A6: Butter | B6: 1 | C6: tbsp | D6: =IF(C6="oz","ozm",IF(C6="tbsp","tbs",IF(C6="fl oz","oz",IF(C6="L","l",IF(C6="mL","ml",IF(C6="lb","lbm",IF(C6="----","F",C6))))))) -> tbs | E6: =IF(AND(D6="F",G6="F"),B6,CONVERT(B6,D6,G6))*'Bl Sayniyé - Sample Recipe'!$C$3/'Bl Sayniyé - Sample Recipe'!$B$3 -> 0.53 | F6: tbsp | G6: =IF(F6="oz","ozm",IF(F6="tbsp","tbs",IF(F6="fl oz","oz",IF(F6="L","l",IF(F6="mL","ml",IF(F6="lb","lbm",IF(F6="----","F",F6))))))) -> tbs
A7: Olive Oil | B7: 120 | C7: mL | D7: =IF(C7="oz","ozm",IF(C7="tbsp","tbs",IF(C7="fl oz","oz",IF(C7="L","l",IF(C7="mL","ml",IF(C7="lb","lbm",IF(C7="----","F",C7))))))) -> ml | E7: =IF(AND(D7="F",G7="F"),B7,CONVERT(B7,D7,G7))*'Bl Sayniyé - Sample Recipe'!$C$3/'Bl Sayniyé - Sample Recipe'!$B$3 -> 63.6 | F7: mL | G7: =IF(F7="oz","ozm",IF(F7="tbsp","tbs",IF(F7="fl oz","oz",IF(F7="L","l",IF(F7="mL","ml",IF(F7="lb","lbm",IF(F7="----","F",F7))))))) -> ml
A8: Pomegranate Molasse | B8: 2 | C8: tbsp | D8: =IF(C8="oz","ozm",IF(C8="tbsp","tbs",IF(C8="fl oz","oz",IF(C8="L","l",IF(C8="mL","ml",IF(C8="lb","lbm",IF(C8="----","F",C8))))))) -> tbs | E8: =IF(AND(D8="F",G8="F"),B8,CONVERT(B8,D8,G8))*'Bl Sayniyé - Sample Recipe'!$C$3/'Bl Sayniyé - Sample Recipe'!$B$3 -> 1.06 | F8: tbsp | G8: =IF(F8="oz","ozm",IF(F8="tbsp","tbs",IF(F8="fl oz","oz",IF(F8="L","l",IF(F8="mL","ml",IF(F8="lb","lbm",IF(F8="----","F",F8))))))) -> tbs
A9: Salt | B9: 2 | C9: tsp | D9: =IF(C9="oz","ozm",IF(C9="tbsp","tbs",IF(C9="fl oz","oz",IF(C9="L","l",IF(C9="mL","ml",IF(C9="lb","lbm",IF(C9="----","F",C9))))))) -> tsp | E9: =IF(AND(D9="F",G9="F"),B9,CONVERT(B9,D9,G9))*'Bl Sayniyé - Sample Recipe'!$C$3/'Bl Sayniyé - Sample Recipe'!$B$3 -> 1.06 | F9: tsp | G9: =IF(F9="oz","ozm",IF(F9="tbsp","tbs",IF(F9="fl oz","oz",IF(F9="L","l",IF(F9="mL","ml",IF(F9="lb","lbm",IF(F9="----","F",F9))))))) -> tsp
A10: Ground Pepper | B10: 1 | C10: tsp | D10: =IF(C10="oz","ozm",IF(C10="tbsp","tbs",IF(C10="fl oz","oz",IF(C10="L","l",IF(C10="mL","ml",IF(C10="lb","lbm",IF(C10="----","F",C10))))))) -> tsp | E10: =IF(AND(D10="F",G10="F"),B10,CONVERT(B10,D10,G10))*'Bl Sayniyé - Sample Recipe'!$C$3/'Bl Sayniyé - Sample Recipe'!$B$3 -> 0.53 | F10: tsp | G10: =IF(F10="oz","ozm",IF(F10="tbsp","tbs",IF(F10="fl oz","oz",IF(F10="L","l",IF(F10="mL","ml",IF(F10="lb","lbm",IF(F10="----","F",F10))))))) -> tsp

Sheet Bl Sayniyé - Drawings

Sheet Feta Kebbé - Sample Recipe
A1: Sample Recipe
B2: Recipe serves | C2: Prepared for
B3: 10 | C3: 5.3

Sheet Feta Kebbé - Recipe
A1: Ingredient | B1: Regular | E1: Small
A2: Meat | B2: 400 | C2: g | D2: =IF(C2="oz","ozm",IF(C2="tbsp","tbs",IF(C2="fl oz","oz",IF(C2="L","l",IF(C2="mL","ml",IF(C2="lb","lbm",IF(C2="----","F",C2))))))) -> g | E2: =IF(AND(D2="F",G2="F"),B2,CONVERT(B2,D2,G2))*'Feta Kebbé - Sample Recipe'!$C$3/'Feta Kebbé - Sample Recipe'!$B$3 -> 212 | F2: g | G2: =IF(F2="oz","ozm",IF(F2="tbsp","tbs",IF(F2="fl oz","oz",IF(F2="L","l",IF(F2="mL","ml",IF(F2="lb","lbm",IF(F2="----","F",F2))))))) -> g
A3: Borghol | B3: 250 | C3: g | D3: =IF(C3="oz","ozm",IF(C3="tbsp","tbs",IF(C3="fl oz","oz",IF(C3="L","l",IF(C3="mL","ml",IF(C3="lb","lbm",IF(C3="----","F",C3))))))) -> g | E3: =IF(AND(D3="F",G3="F"),B3,CONVERT(B3,D3,G3))*'Feta Kebbé - Sample Recipe'!$C$3/'Feta Kebbé - Sample Recipe'!$B$3 -> 132.5 | F3: g | G3: =IF(F3="oz","ozm",IF(F3="tbsp","tbs",IF(F3="fl oz","oz",IF(F3="L","l",IF(F3="mL","ml",IF(F3="lb","lbm",IF(F3="----","F",F3))))))) -> g
A4: Feta | B4: 150 | C4: g | D4: =IF(C4="oz","ozm",IF(C4="tbsp","tbs",IF(C4="fl oz","oz",IF(C4="L","l",IF(C4="mL","ml",IF(C4="lb","lbm",IF(C4="----","F",C4))))))) -> g | E4: =IF(AND(D4="F",G4="F"),B4,CONVERT(B4,D4,G4))*'Feta Kebbé - Sample Recipe'!$C$3/'Feta Kebbé - Sample Recipe'!$B$3 -> 79.5 | F4: g | G4: =IF(F4="oz","ozm",IF(F4="tbsp","tbs",IF(F4="fl oz","oz",IF(F4="L","l",IF(F4="mL","ml",IF(F4="lb","lbm",IF(F4="----","F",F4))))))) -> g
A5: Onion | B5: 160 | C5: g | D5: =IF(C5="oz","ozm",IF(C5="tbsp","tbs",IF(C5="fl oz","oz",IF(C5="L","l",IF(C5="mL","ml",IF(C5="lb","lbm",IF(C5="----","F",C5))))))) -> g | E5: =IF(AND(D5="F",G5="F"),B5,CONVERT(B5,D5,G5))*'Feta Kebbé - Sample Recipe'!$C$3/'Feta Kebbé - Sample Recipe'!$B$3 -> 84.8 | F5: g | G5: =IF(F5="oz","ozm",IF(F5="tbsp","tbs",IF(F5="fl oz","oz",IF(F5="L","l",IF(F5="mL","ml",IF(F5="lb","lbm",IF(F5="----","F",F5))))))) -> g
A6: Walnuts | B6: 30 | C6: g | D6: =IF(C6="oz","ozm",IF(C6="tbsp","tbs",IF(C6="fl oz","oz",IF(C6="L","l",IF(C6="mL","ml",IF(C6="lb","lbm",IF(C6="----","F",C6))))))) -> g | E6: =IF(AND(D6="F",G6="F"),B6,CONVERT(B6,D6,G6))*'Feta Kebbé - Sample Recipe'!$C$3/'Feta Kebbé - Sample Recipe'!$B$3 -> 15.9 | F6: g | G6: =IF(F6="oz","ozm",IF(F6="tbsp","tbs",IF(F6="fl oz","oz",IF(F6="L","l",IF(F6="mL","ml",IF(F6="lb","lbm",IF(F6="----","F",F6))))))) -> g
A7: Olive Oil | B7: 120 | C7: mL | D7: =IF(C7="oz","ozm",IF(C7="tbsp","tbs",IF(C7="fl oz","oz",IF(C7="L","l",IF(C7="mL","ml",IF(C7="lb","lbm",IF(C7="----","F",C7))))))) -> ml | E7: =IF(AND(D7="F",G7="F"),B7,CONVERT(B7,D7,G7))*'Feta Kebbé - Sample Recipe'!$C$3/'Feta Kebbé - Sample Recipe'!$B$3 -> 63.6 | F7: mL | G7: =IF(F7="oz","ozm",IF(F7="tbsp","tbs",IF(F7="fl oz","oz",IF(F7="L","l",IF(F7="mL","ml",IF(F7="lb","lbm",IF(F7="----","F",F7))))))) -> ml
A8: Oregano | B8: 2 | C8: tsp | D8: =IF(C8="oz","ozm",IF(C8="tbsp","tbs",IF(C8="fl oz","oz",IF(C8="L","l",IF(C8="mL","ml",IF(C8="lb","lbm",IF(C8="----","F",C8))))))) -> tsp | E8: =IF(AND(D8="F",G8="F"),B8,CONVERT(B8,D8,G8))*'Feta Kebbé - Sample Recipe'!$C$3/'Feta Kebbé - Sample Recipe'!$B$3 -> 0.35333333 | F8: tbsp | G8: =IF(F8="oz","ozm",IF(F8="tbsp","tbs",IF(F8="fl oz","oz",IF(F8="L","l",IF(F8="mL","ml",IF(F8="lb","lbm",IF(F8="----","F",F8))))))) -> tbs
A9: Salt | B9: 2 | C9: tsp | D9: =IF(C9="oz","ozm",IF(C9="tbsp","tbs",IF(C9="fl oz","oz",IF(C9="L","l",IF(C9="mL","ml",IF(C9="lb","lbm",IF(C9="----","F",C9))))))) -> tsp | E9: =IF(AND(D9="F",G9="F"),B9,CONVERT(B9,D9,G9))*'Feta Kebbé - Sample Recipe'!$C$3/'Feta Kebbé - Sample Recipe'!$B$3 -> 1.06 | F9: tsp | G9: =IF(F9="oz","ozm",IF(F9="tbsp","tbs",IF(F9="fl oz","oz",IF(F9="L","l",IF(F9="mL","ml",IF(F9="lb","lbm",IF(F9="----","F",F9))))))) -> tsp
A10: White Pepper | B10: 1 | C10: tsp | D10: =IF(C10="oz","ozm",IF(C10="tbsp","tbs",IF(C10="fl oz","oz",IF(C10="L","l",IF(C10="mL","ml",IF(C10="lb","lbm",IF(C10="----","F",C10))))))) -> tsp | E10: =IF(AND(D10="F",G10="F"),B10,CONVERT(B10,D10,G10))*'Feta Kebbé - Sample Recipe'!$C$3/'Feta Kebbé - Sample Recipe'!$B$3 -> 0.53 | F10: tsp | G10: =IF(F10="oz","ozm",IF(F10="tbsp","tbs",IF(F10="fl oz","oz",IF(F10="L","l",IF(F10="mL","ml",IF(F10="lb","lbm",IF(F10="----","F",F10))))))) -> tsp
A11: Paprika | B11: 1 | C11: tsp | D11: =IF(C11="oz","ozm",IF(C11="tbsp","tbs",IF(C11="fl oz","oz",IF(C11="L","l",IF(C11="mL","ml",IF(C11="lb","lbm",IF(C11="----","F",C11))))))) -> tsp | E11: =IF(AND(D11="F",G11="F"),B11,CONVERT(B11,D11,G11))*'Feta Kebbé - Sample Recipe'!$C$3/'Feta Kebbé - Sample Recipe'!$B$3 -> 0.53 | F11: tsp | G11: =IF(F11="oz","ozm",IF(F11="tbsp","tbs",IF(F11="fl oz","oz",IF(F11="L","l",IF(F11="mL","ml",IF(F11="lb","lbm",IF(F11="----","F",F11))))))) -> tsp

Sheet Feta Kebbé - Drawings

Sheet Onion & Pine - Sample Recipe
A1: Sample Recipe
B2: Recipe serves | C2: Prepared for
B3: 10 | C3: 5.3

Sheet Onion & Pine - Recipe
A1: Ingredient | B1: Regular | E1: Small
A2: Meat | B2: 250 | C2: g | D2: =IF(C2="oz","ozm",IF(C2="tbsp","tbs",IF(C2="fl oz","oz",IF(C2="L","l",IF(C2="mL","ml",IF(C2="lb","lbm",IF(C2="----","F",C2))))))) -> g | E2: =IF(AND(D2="F",G2="F"),B2,CONVERT(B2,D2,G2))*'Onion & Pine - Sample Recipe'!$C$3/'Onion & Pine - Sample Recipe'!$B$3 -> 132.5 | F2: g | G2: =IF(F2="oz","ozm",IF(F2="tbsp","tbs",IF(F2="fl oz","oz",IF(F2="L","l",IF(F2="mL","ml",IF(F2="lb","lbm",IF(F2="----","F",F2))))))) -> g
A3: Borghol | B3: 130 | C3: g | D3: =IF(C3="oz","ozm",IF(C3="tbsp","tbs",IF(C3="fl oz","oz",IF(C3="L","l",IF(C3="mL","ml",IF(C3="lb","lbm",IF(C3="----","F",C3))))))) -> g | E3: =IF(AND(D3="F",G3="F"),B3,CONVERT(B3,D3,G3))*'Onion & Pine - Sample Recipe'!$C$3/'Onion & Pine - Sample Recipe'!$B$3 -> 68.9 | F3: g | G3: =IF(F3="oz","ozm",IF(F3="tbsp","tbs",IF(F3="fl oz","oz",IF(F3="L","l",IF(F3="mL","ml",IF(F3="lb","lbm",IF(F3="----","F",F3))))))) -> g
A4: Pine nuts | B4: 30 | C4: g | D4: =IF(C4="oz","ozm",IF(C4="tbsp","tbs",IF(C4="fl oz","oz",IF(C4="L","l",IF(C4="mL","ml",IF(C4="lb","lbm",IF(C4="----","F",C4))))))) -> g | E4: =IF(AND(D4="F",G4="F"),B4,CONVERT(B4,D4,G4))*'Onion & Pine - Sample Recipe'!$C$3/'Onion & Pine - Sample Recipe'!$B$3 -> 15.9 | F4: g | G4: =IF(F4="oz","ozm",IF(F4="tbsp","tbs",IF(F4="fl oz","oz",IF(F4="L","l",IF(F4="mL","ml",IF(F4="lb","lbm",IF(F4="----","F",F4))))))) -> g
A5: Onion | B5: 160 | C5: g | D5: =IF(C5="oz","ozm",IF(C5="tbsp","tbs",IF(C5="fl oz","oz",IF(C5="L","l",IF(C5="mL","ml",IF(C5="lb","lbm",IF(C5="----","F",C5))))))) -> g | E5: =IF(AND(D5="F",G5="F"),B5,CONVERT(B5,D5,G5))*'Onion & Pine - Sample Recipe'!$C$3/'Onion & Pine - Sample Recipe'!$B$3 -> 84.8 | F5: g | G5: =IF(F5="oz","ozm",IF(F5="tbsp","tbs",IF(F5="fl oz","oz",IF(F5="L","l",IF(F5="mL","ml",IF(F5="lb","lbm",IF(F5="----","F",F5))))))) -> g
A6: Black Pepper | B6: 1 | C6: tsp | D6: =IF(C6="oz","ozm",IF(C6="tbsp","tbs",IF(C6="fl oz","oz",IF(C6="L","l",IF(C6="mL","ml",IF(C6="lb","lbm",IF(C6="----","F",C6))))))) -> tsp | E6: =IF(AND(D6="F",G6="F"),B6,CONVERT(B6,D6,G6))*'Onion & Pine - Sample Recipe'!$C$3/'Onion & Pine - Sample Recipe'!$B$3 -> 0.53 | F6: tsp | G6: =IF(F6="oz","ozm",IF(F6="tbsp","tbs",IF(F6="fl oz","oz",IF(F6="L","l",IF(F6="mL","ml",IF(F6="lb","lbm",IF(F6="----","F",F6))))))) -> tsp
A7: Olive Oil | B7: 120 | C7: mL | D7: =IF(C7="oz","ozm",IF(C7="tbsp","tbs",IF(C7="fl oz","oz",IF(C7="L","l",IF(C7="mL","ml",IF(C7="lb","lbm",IF(C7="----","F",C7))))))) -> ml | E7: =IF(AND(D7="F",G7="F"),B7,CONVERT(B7,D7,G7))*'Onion & Pine - Sample Recipe'!$C$3/'Onion & Pine - Sample Recipe'!$B$3 -> 63.6 | F7: mL | G7: =IF(F7="oz","ozm",IF(F7="tbsp","tbs",IF(F7="fl oz","oz",IF(F7="L","l",IF(F7="mL","ml",IF(F7="lb","lbm",IF(F7="----","F",F7))))))) -> ml
A8: Salt | B8: 2 | C8: tsp | D8: =IF(C8="oz","ozm",IF(C8="tbsp","tbs",IF(C8="fl oz","oz",IF(C8="L","l",IF(C8="mL","ml",IF(C8="lb","lbm",IF(C8="----","F",C8))))))) -> tsp | E8: =IF(AND(D8="F",G8="F"),B8,CONVERT(B8,D8,G8))*'Onion & Pine - Sample Recipe'!$C$3/'Onion & Pine - Sample Recipe'!$B$3 -> 0.35333333 | F8: tbsp | G8: =IF(F8="oz","ozm",IF(F8="tbsp","tbs",IF(F8="fl oz","oz",IF(F8="L","l",IF(F8="mL","ml",IF(F8="lb","lbm",IF(F8="----","F",F8))))))) -> tbs
A9: Ground Pepper | B9: 1 | C9: tsp | D9: =IF(C9="oz","ozm",IF(C9="tbsp","tbs",IF(C9="fl oz","oz",IF(C9="L","l",IF(C9="mL","ml",IF(C9="lb","lbm",IF(C9="----","F",C9))))))) -> tsp | E9: =IF(AND(D9="F",G9="F"),B9,CONVERT(B9,D9,G9))*'Onion & Pine - Sample Recipe'!$C$3/'Onion & Pine - Sample Recipe'!$B$3 -> 0.53 | F9: tsp | G9: =IF(F9="oz","ozm",IF(F9="tbsp","tbs",IF(F9="fl oz","oz",IF(F9="L","l",IF(F9="mL","ml",IF(F9="lb","lbm",IF(F9="----","F",F9))))))) -> tsp
D10: =IF(C10="oz","ozm",IF(C10="tbsp","tbs",IF(C10="fl oz","oz",IF(C10="L","l",IF(C10="mL","ml",IF(C10="lb","lbm",IF(C10="----","F",C10))))))) | G10: =IF(F10="oz","ozm",IF(F10="tbsp","tbs",IF(F10="fl oz","oz",IF(F10="L","l",IF(F10="mL","ml",IF(F10="lb","lbm",IF(F10="----","F",F10)))))))

Sheet Onion & Pine - Drawings

Sheet Nayyé - Sample Recipe
A1: Sample Recipe
B2: Recipe serves | C2: Prepared for
B3: 10 | C3: 5.3

Sheet Nayyé - Recipe
A1: Ingredient | B1: Regular | E1: Small
A2: Meat | B2: 500 | C2: g | D2: =IF(C2="oz","ozm",IF(C2="tbsp","tbs",IF(C2="fl oz","oz",IF(C2="L","l",IF(C2="mL","ml",IF(C2="lb","lbm",IF(C2="----","F",C2))))))) -> g | E2: =IF(AND(D2="F",G2="F"),B2,CONVERT(B2,D2,G2))*'Nayyé - Sample Recipe'!$C$3/'Nayyé - Sample Recipe'!$B$3 -> 265 | F2: g | G2: =IF(F2="oz","ozm",IF(F2="tbsp","tbs",IF(F2="fl oz","oz",IF(F2="L","l",IF(F2="mL","ml",IF(F2="lb","lbm",IF(F2="----","F",F2))))))) -> g
A3: Borghol | B3: 60 | C3: g | D3: =IF(C3="oz","ozm",IF(C3="tbsp","tbs",IF(C3="fl oz","oz",IF(C3="L","l",IF(C3="mL","ml",IF(C3="lb","lbm",IF(C3="----","F",C3))))))) -> g | E3: =IF(AND(D3="F",G3="F"),B3,CONVERT(B3,D3,G3))*'Nayyé - Sample Recipe'!$C$3/'Nayyé - Sample Recipe'!$B$3 -> 31.8 | F3: g | G3: =IF(F3="oz","ozm",IF(F3="tbsp","tbs",IF(F3="fl oz","oz",IF(F3="L","l",IF(F3="mL","ml",IF(F3="lb","lbm",IF(F3="----","F",F3))))))) -> g
A4: Salt | B4: 2 | C4: tsp | D4: =IF(C4="oz","ozm",IF(C4="tbsp","tbs",IF(C4="fl oz","oz",IF(C4="L","l",IF(C4="mL","ml",IF(C4="lb","lbm",IF(C4="----","F",C4))))))) -> tsp | E4: =IF(AND(D4="F",G4="F"),B4,CONVERT(B4,D4,G4))*'Nayyé - Sample Recipe'!$C$3/'Nayyé - Sample Recipe'!$B$3 -> 0.35333333 | F4: tbsp | G4: =IF(F4="oz","ozm",IF(F4="tbsp","tbs",IF(F4="fl oz","oz",IF(F4="L","l",IF(F4="mL","ml",IF(F4="lb","lbm",IF(F4="----","F",F4))))))) -> tbs
A5: Spring Onion | B5: 100 | C5: g | D5: =IF(C5="oz","ozm",IF(C5="tbsp","tbs",IF(C5="fl oz","oz",IF(C5="L","l",IF(C5="mL","ml",IF(C5="lb","lbm",IF(C5="----","F",C5))))))) -> g | E5: 50 | F5: g | G5: =IF(F5="oz","ozm",IF(F5="tbsp","tbs",IF(F5="fl oz","oz",IF(F5="L","l",IF(F5="mL","ml",IF(F5="lb","lbm",IF(F5="----","F",F5))))))) -> g
A6: Mint | B6: 100 | C6: g | D6: =IF(C6="oz","ozm",IF(C6="tbsp","tbs",IF(C6="fl oz","oz",IF(C6="L","l",IF(C6="mL","ml",IF(C6="lb","lbm",IF(C6="----","F",C6))))))) -> g | E6: =IF(AND(D6="F",G6="F"),B6,CONVERT(B6,D6,G6))*'Nayyé - Sample Recipe'!$C$3/'Nayyé - Sample Recipe'!$B$3 -> 53 | F6: g | G6: =IF(F6="oz","ozm",IF(F6="tbsp","tbs",IF(F6="fl oz","oz",IF(F6="L","l",IF(F6="mL","ml",IF(F6="lb","lbm",IF(F6="----","F",F6))))))) -> g
D7: =IF(C7="oz","ozm",IF(C7="tbsp","tbs",IF(C7="fl oz","oz",IF(C7="L","l",IF(C7="mL","ml",IF(C7="lb","lbm",IF(C7="----","F",C7))))))) | G7: =IF(F7="oz","ozm",IF(F7="tbsp","tbs",IF(F7="fl oz","oz",IF(F7="L","l",IF(F7="mL","ml",IF(F7="lb","lbm",IF(F7="----","F",F7)))))))
D8: =IF(C8="oz","ozm",IF(C8="tbsp","tbs",IF(C8="fl oz","oz",IF(C8="L","l",IF(C8="mL","ml",IF(C8="lb","lbm",IF(C8="----","F",C8))))))) -> 0 | G8: =IF(F8="oz","ozm",IF(F8="tbsp","tbs",IF(F8="fl oz","oz",IF(F8="L","l",IF(F8="mL","ml",IF(F8="lb","lbm",IF(F8="----","F",F8))))))) -> 0
D9: =IF(C9="oz","ozm",IF(C9="tbsp","tbs",IF(C9="fl oz","oz",IF(C9="L","l",IF(C9="mL","ml",IF(C9="lb","lbm",IF(C9="----","F",C9))))))) | G9: =IF(F9="oz","ozm",IF(F9="tbsp","tbs",IF(F9="fl oz","oz",IF(F9="L","l",IF(F9="mL","ml",IF(F9="lb","lbm",IF(F9="----","F",F9))))))) -> 0
D10: =IF(C10="oz","ozm",IF(C10="tbsp","tbs",IF(C10="fl oz","oz",IF(C10="L","l",IF(C10="mL","ml",IF(C10="lb","lbm",IF(C10="----","F",C10))))))) | G10: =IF(F10="oz","ozm",IF(F10="tbsp","tbs",IF(F10="fl oz","oz",IF(F10="L","l",IF(F10="mL","ml",IF(F10="lb","lbm",IF(F10="----","F",F10)))))))

Sheet Nayyé - Drawings

Sheet Hommos Kebbé - Sample Recipe
A1: Sample Recipe
B2: Recipe serves | C2: Prepared for
B3: 10 | C3: 5.3

Sheet Hommos Kebbé - Recipe
A1: Ingredient | B1: Regular | E1: Small
A2: Chickpeas | B2: 0.5 | C2: cup | D2: =IF(C2="oz","ozm",IF(C2="tbsp","tbs",IF(C2="fl oz","oz",IF(C2="L","l",IF(C2="mL","ml",IF(C2="lb","lbm",IF(C2="----","F",C2))))))) -> cup | E2: =IF(AND(D2="F",G2="F"),B2,CONVERT(B2,D2,G2))*'Hommos Kebbé - Sample Recipe'!$C$3/'Hommos Kebbé - Sample Recipe'!$B$3 -> 0.265 | F2: cup | G2: =IF(F2="oz","ozm",IF(F2="tbsp","tbs",IF(F2="fl oz","oz",IF(F2="L","l",IF(F2="mL","ml",IF(F2="lb","lbm",IF(F2="----","F",F2))))))) -> cup
A3: Borghol | B3: 0.75 | C3: cup | D3: =IF(C3="oz","ozm",IF(C3="tbsp","tbs",IF(C3="fl oz","oz",IF(C3="L","l",IF(C3="mL","ml",IF(C3="lb","lbm",IF(C3="----","F",C3))))))) -> cup | E3: =IF(AND(D3="F",G3="F"),B3,CONVERT(B3,D3,G3))*'Hommos Kebbé - Sample Recipe'!$C$3/'Hommos Kebbé - Sample Recipe'!$B$3 -> 0.3975 | F3: cup | G3: =IF(F3="oz","ozm",IF(F3="tbsp","tbs",IF(F3="fl oz","oz",IF(F3="L","l",IF(F3="mL","ml",IF(F3="lb","lbm",IF(F3="----","F",F3))))))) -> cup
A4: Flour | B4: 0.5 | C4: cup | D4: =IF(C4="oz","ozm",IF(C4="tbsp","tbs",IF(C4="fl oz","oz",IF(C4="L","l",IF(C4="mL","ml",IF(C4="lb","lbm",IF(C4="----","F",C4))))))) -> cup | E4: =IF(AND(D4="F",G4="F"),B4,CONVERT(B4,D4,G4))*'Hommos Kebbé - Sample Recipe'!$C$3/'Hommos Kebbé - Sample Recipe'!$B$3 -> 0.265 | F4: cup | G4: =IF(F4="oz","ozm",IF(F4="tbsp","tbs",IF(F4="fl oz","oz",IF(F4="L","l",IF(F4="mL","ml",IF(F4="lb","lbm",IF(F4="----","F",F4))))))) -> cup
A5: Onion | B5: 100 | C5: g | D5: =IF(C5="oz","ozm",IF(C5="tbsp","tbs",IF(C5="fl oz","oz",IF(C5="L","l",IF(C5="mL","ml",IF(C5="lb","lbm",IF(C5="----","F",C5))))))) -> g | E5: =IF(AND(D5="F",G5="F"),B5,CONVERT(B5,D5,G5))*'Hommos Kebbé - Sample Recipe'!$C$3/'Hommos Kebbé - Sample Recipe'!$B$3 -> 53 | F5: g | G5: =IF(F5="oz","ozm",IF(F5="tbsp","tbs",IF(F5="fl oz","oz",IF(F5="L","l",IF(F5="mL","ml",IF(F5="lb","lbm",IF(F5="----","F",F5))))))) -> g
A6: Dried Mint | B6: 1 | C6: tbsp | D6: =IF(C6="oz","ozm",IF(C6="tbsp","tbs",IF(C6="fl oz","oz",IF(C6="L","l",IF(C6="mL","ml",IF(C6="lb","lbm",IF(C6="----","F",C6))))))) -> tbs | E6: =IF(AND(D6="F",G6="F"),B6,CONVERT(B6,D6,G6))*'Hommos Kebbé - Sample Recipe'!$C$3/'Hommos Kebbé - Sample Recipe'!$B$3 -> 0.53 | F6: tbsp | G6: =IF(F6="oz","ozm",IF(F6="tbsp","tbs",IF(F6="fl oz","oz",IF(F6="L","l",IF(F6="mL","ml",IF(F6="lb","lbm",IF(F6="----","F",F6))))))) -> tbs
A7: Olive Oil | B7: 120 | C7: mL | D7: =IF(C7="oz","ozm",IF(C7="tbsp","tbs",IF(C7="fl oz","oz",IF(C7="L","l",IF(C7="mL","ml",IF(C7="lb","lbm",IF(C7="----","F",C7))))))) -> ml | E7: =IF(AND(D7="F",G7="F"),B7,CONVERT(B7,D7,G7))*'Hommos Kebbé - Sample Recipe'!$C$3/'Hommos Kebbé - Sample Recipe'!$B$3 -> 63.6 | F7: mL | G7: =IF(F7="oz","ozm",IF(F7="tbsp","tbs",IF(F7="fl oz","oz",IF(F7="L","l",IF(F7="mL","ml",IF(F7="lb","lbm",IF(F7="----","F",F7))))))) -> ml
A8: Crushed Kaak | B8: 1 | C8: tbsp | D8: =IF(C8="oz","ozm",IF(C8="tbsp","tbs",IF(C8="fl oz","oz",IF(C8="L","l",IF(C8="mL","ml",IF(C8="lb","lbm",IF(C8="----","F",C8))))))) -> tbs | E8: =IF(AND(D8="F",G8="F"),B8,CONVERT(B8,D8,G8))*'Hommos Kebbé - Sample Recipe'!$C$3/'Hommos Kebbé - Sample Recipe'!$B$3 -> 0.53 | F8: tbsp | G8: =IF(F8="oz","ozm",IF(F8="tbsp","tbs",IF(F8="fl oz","oz",IF(F8="L","l",IF(F8="mL","ml",IF(F8="lb","lbm",IF(F8="----","F",F8))))))) -> tbs
A9: Salt | B9: 1 | C9: tbsp | D9: =IF(C9="oz","ozm",IF(C9="tbsp","tbs",IF(C9="fl oz","oz",IF(C9="L","l",IF(C9="mL","ml",IF(C9="lb","lbm",IF(C9="----","F",C9))))))) -> tbs | E9: =IF(AND(D9="F",G9="F"),B9,CONVERT(B9,D9,G9))*'Hommos Kebbé - Sample Recipe'!$C$3/'Hommos Kebbé - Sample Recipe'!$B$3 -> 0.53 | F9: tbsp | G9: =IF(F9="oz","ozm",IF(F9="tbsp","tbs",IF(F9="fl oz","oz",IF(F9="L","l",IF(F9="mL","ml",IF(F9="lb","lbm",IF(F9="----","F",F9))))))) -> tbs
A10: White Pepper | B10: 1 | C10: tsp | D10: =IF(C10="oz","ozm",IF(C10="tbsp","tbs",IF(C10="fl oz","oz",IF(C10="L","l",IF(C10="mL","ml",IF(C10="lb","lbm",IF(C10="----","F",C10))))))) -> tsp | E10: =IF(AND(D10="F",G10="F"),B10,CONVERT(B10,D10,G10))*'Hommos Kebbé - Sample Recipe'!$C$3/'Hommos Kebbé - Sample Recipe'!$B$3 -> 0.53 | F10: tsp | G10: =IF(F10="oz","ozm",IF(F10="tbsp","tbs",IF(F10="fl oz","oz",IF(F10="L","l",IF(F10="mL","ml",IF(F10="lb","lbm",IF(F10="----","F",F10))))))) -> tsp

Sheet Hommos Kebbé - Drawings

Sheet Bou Emné - Sample Recipe
A1: Sample Recipe
B2: Recipe serves | C2: Prepared for
B3: 10 | C3: 5.3

Sheet Bou Emné - Recipe
A1: Ingredient | B1: Regular | E1: Small
A2: Chickpeas | B2: 0.5 | C2: cup | D2: =IF(C2="oz","ozm",IF(C2="tbsp","tbs",IF(C2="fl oz","oz",IF(C2="L","l",IF(C2="mL","ml",IF(C2="lb","lbm",IF(C2="----","F",C2))))))) -> cup | E2: =IF(AND(D2="F",G2="F"),B2,CONVERT(B2,D2,G2))*'Bou Emné - Sample Recipe'!$C$3/'Bou Emné - Sample Recipe'!$B$3 -> 0.265 | F2: cup | G2: =IF(F2="oz","ozm",IF(F2="tbsp","tbs",IF(F2="fl oz","oz",IF(F2="L","l",IF(F2="mL","ml",IF(F2="lb","lbm",IF(F2="----","F",F2))))))) -> cup
A3: Borghol | B3: 1 | C3: cup | D3: =IF(C3="oz","ozm",IF(C3="tbsp","tbs",IF(C3="fl oz","oz",IF(C3="L","l",IF(C3="mL","ml",IF(C3="lb","lbm",IF(C3="----","F",C3))))))) -> cup | E3: =IF(AND(D3="F",G3="F"),B3,CONVERT(B3,D3,G3))*'Bou Emné - Sample Recipe'!$C$3/'Bou Emné - Sample Recipe'!$B$3 -> 0.53 | F3: cup | G3: =IF(F3="oz","ozm",IF(F3="tbsp","tbs",IF(F3="fl oz","oz",IF(F3="L","l",IF(F3="mL","ml",IF(F3="lb","lbm",IF(F3="----","F",F3))))))) -> cup
A4: Flour | B4: 0.75 | C4: cup | D4: =IF(C4="oz","ozm",IF(C4="tbsp","tbs",IF(C4="fl oz","oz",IF(C4="L","l",IF(C4="mL","ml",IF(C4="lb","lbm",IF(C4="----","F",C4))))))) -> cup | E4: =IF(AND(D4="F",G4="F"),B4,CONVERT(B4,D4,G4))*'Bou Emné - Sample Recipe'!$C$3/'Bou Emné - Sample Recipe'!$B$3 -> 0.3975 | F4: cup | G4: =IF(F4="oz","ozm",IF(F4="tbsp","tbs",IF(F4="fl oz","oz",IF(F4="L","l",IF(F4="mL","ml",IF(F4="lb","lbm",IF(F4="----","F",F4))))))) -> cup
A5: Onion | B5: 100 | C5: g | D5: =IF(C5="oz","ozm",IF(C5="tbsp","tbs",IF(C5="fl oz","oz",IF(C5="L","l",IF(C5="mL","ml",IF(C5="lb","lbm",IF(C5="----","F",C5))))))) -> g | E5: =IF(AND(D5="F",G5="F"),B5,CONVERT(B5,D5,G5))*'Bou Emné - Sample Recipe'!$C$3/'Bou Emné - Sample Recipe'!$B$3 -> 53 | F5: g | G5: =IF(F5="oz","ozm",IF(F5="tbsp","tbs",IF(F5="fl oz","oz",IF(F5="L","l",IF(F5="mL","ml",IF(F5="lb","lbm",IF(F5="----","F",F5))))))) -> g
A6: Dried Mint | B6: 1 | C6: tbsp | D6: =IF(C6="oz","ozm",IF(C6="tbsp","tbs",IF(C6="fl oz","oz",IF(C6="L","l",IF(C6="mL","ml",IF(C6="lb","lbm",IF(C6="----","F",C6))))))) -> tbs | E6: =IF(AND(D6="F",G6="F"),B6,CONVERT(B6,D6,G6))*'Bou Emné - Sample Recipe'!$C$3/'Bou Emné - Sample Recipe'!$B$3 -> 0.53 | F6: tbsp | G6: =IF(F6="oz","ozm",IF(F6="tbsp","tbs",IF(F6="fl oz","oz",IF(F6="L","l",IF(F6="mL","ml",IF(F6="lb","lbm",IF(F6="----","F",F6))))))) -> tbs
A7: Olive Oil | B7: 120 | C7: mL | D7: =IF(C7="oz","ozm",IF(C7="tbsp","tbs",IF(C7="fl oz","oz",IF(C7="L","l",IF(C7="mL","ml",IF(C7="lb","lbm",IF(C7="----","F",C7))))))) -> ml | E7: =IF(AND(D7="F",G7="F"),B7,CONVERT(B7,D7,G7))*'Bou Emné - Sample Recipe'!$C$3/'Bou Emné - Sample Recipe'!$B$3 -> 63.6 | F7: mL | G7: =IF(F7="oz","ozm",IF(F7="tbsp","tbs",IF(F7="fl oz","oz",IF(F7="L","l",IF(F7="mL","ml",IF(F7="lb","lbm",IF(F7="----","F",F7))))))) -> ml
A8: Pomegranate Molasse | B8: 1 | C8: tbsp | D8: =IF(C8="oz","ozm",IF(C8="tbsp","tbs",IF(C8="fl oz","oz",IF(C8="L","l",IF(C8="mL","ml",IF(C8="lb","lbm",IF(C8="----","F",C8))))))) -> tbs | E8: =IF(AND(D8="F",G8="F"),B8,CONVERT(B8,D8,G8))*'Bou Emné - Sample Recipe'!$C$3/'Bou Emné - Sample Recipe'!$B$3 -> 0.53 | F8: tbsp | G8: =IF(F8="oz","ozm",IF(F8="tbsp","tbs",IF(F8="fl oz","oz",IF(F8="L","l",IF(F8="mL","ml",IF(F8="lb","lbm",IF(F8="----","F",F8))))))) -> tbs
A9: Pomegranate | B9: 40 | C9: g | D9: =IF(C9="oz","ozm",IF(C9="tbsp","tbs",IF(C9="fl oz","oz",IF(C9="L","l",IF(C9="mL","ml",IF(C9="lb","lbm",IF(C9="----","F",C9))))))) -> g | E9: 25 | F9: g | G9: =IF(F9="oz","ozm",IF(F9="tbsp","tbs",IF(F9="fl oz","oz",IF(F9="L","l",IF(F9="mL","ml",IF(F9="lb","lbm",IF(F9="----","F",F9))))))) -> g
A10: Salt | B10: 1 | C10: tbsp | D10: =IF(C10="oz","ozm",IF(C10="tbsp","tbs",IF(C10="fl oz","oz",IF(C10="L","l",IF(C10="mL","ml",IF(C10="lb","lbm",IF(C10="----","F",C10))))))) -> tbs | E10: =IF(AND(D10="F",G10="F"),B10,CONVERT(B10,D10,G10))*'Bou Emné - Sample Recipe'!$C$3/'Bou Emné - Sample Recipe'!$B$3 -> 0.53 | F10: tbsp | G10: =IF(F10="oz","ozm",IF(F10="tbsp","tbs",IF(F10="fl oz","oz",IF(F10="L","l",IF(F10="mL","ml",IF(F10="lb","lbm",IF(F10="----","F",F10))))))) -> tbs
A11: White Pepper | B11: 1 | C11: tsp | D11: =IF(C11="oz","ozm",IF(C11="tbsp","tbs",IF(C11="fl oz","oz",IF(C11="L","l",IF(C11="mL","ml",IF(C11="lb","lbm",IF(C11="----","F",C11))))))) -> tsp | E11: =IF(AND(D11="F",G11="F"),B11,CONVERT(B11,D11,G11))*'Bou Emné - Sample Recipe'!$C$3/'Bou Emné - Sample Recipe'!$B$3 -> 0.53 | F11: tsp | G11: =IF(F11="oz","ozm",IF(F11="tbsp","tbs",IF(F11="fl oz","oz",IF(F11="L","l",IF(F11="mL","ml",IF(F11="lb","lbm",IF(F11="----","F",F11))))))) -> tsp
A12: Cumin | B12: 1 | C12: tsp | D12: =IF(C12="oz","ozm",IF(C12="tbsp","tbs",IF(C12="fl oz","oz",IF(C12="L","l",IF(C12="mL","ml",IF(C12="lb","lbm",IF(C12="----","F",C12))))))) -> tsp | E12: =IF(AND(D12="F",G12="F"),B12,CONVERT(B12,D12,G12))*'Bou Emné - Sample Recipe'!$C$3/'Bou Emné - Sample Recipe'!$B$3 -> 0.53 | F12: tsp | G12: =IF(F12="oz","ozm",IF(F12="tbsp","tbs",IF(F12="fl oz","oz",IF(F12="L","l",IF(F12="mL","ml",IF(F12="lb","lbm",IF(F12="----","F",F12))))))) -> tsp
D13: =IF(C13="oz","ozm",IF(C13="tbsp","tbs",IF(C13="fl oz","oz",IF(C13="L","l",IF(C13="mL","ml",IF(C13="lb","lbm",IF(C13="----","F",C13))))))) | G13: =IF(F13="oz","ozm",IF(F13="tbsp","tbs",IF(F13="fl oz","oz",IF(F13="L","l",IF(F13="mL","ml",IF(F13="lb","lbm",IF(F13="----","F",F13))))))) -> 0
D14: =IF(C14="oz","ozm",IF(C14="tbsp","tbs",IF(C14="fl oz","oz",IF(C14="L","l",IF(C14="mL","ml",IF(C14="lb","lbm",IF(C14="----","F",C14))))))) | G14: =IF(F14="oz","ozm",IF(F14="tbsp","tbs",IF(F14="fl oz","oz",IF(F14="L","l",IF(F14="mL","ml",IF(F14="lb","lbm",IF(F14="----","F",F14)))))))

Sheet Bou Emné - Drawings

Sheet La'tine - Sample Recipe
A1: Sample Recipe
B2: Recipe serves | C2: Prepared for
B3: 10 | C3: 5.3

Sheet La'tine - Recipe
A1: Ingredient | B1: Regular | E1: Small
A2: Pumpkin | B2: 2 | C2: kg | D2: =IF(C2="oz","ozm",IF(C2="tbsp","tbs",IF(C2="fl oz","oz",IF(C2="L","l",IF(C2="mL","ml",IF(C2="lb","lbm",IF(C2="----","F",C2))))))) -> kg | E2: =IF(AND(D2="F",G2="F"),B2,CONVERT(B2,D2,G2))*'La''tine - Sample Recipe'!$C$3/'La''tine - Sample Recipe'!$B$3 -> 1.06 | F2: kg | G2: =IF(F2="oz","ozm",IF(F2="tbsp","tbs",IF(F2="fl oz","oz",IF(F2="L","l",IF(F2="mL","ml",IF(F2="lb","lbm",IF(F2="----","F",F2))))))) -> kg
A3: Borghol | B3: 600 | C3: g | D3: =IF(C3="oz","ozm",IF(C3="tbsp","tbs",IF(C3="fl oz","oz",IF(C3="L","l",IF(C3="mL","ml",IF(C3="lb","lbm",IF(C3="----","F",C3))))))) -> g | E3: =IF(AND(D3="F",G3="F"),B3,CONVERT(B3,D3,G3))*'La''tine - Sample Recipe'!$C$3/'La''tine - Sample Recipe'!$B$3 -> 318 | F3: g | G3: =IF(F3="oz","ozm",IF(F3="tbsp","tbs",IF(F3="fl oz","oz",IF(F3="L","l",IF(F3="mL","ml",IF(F3="lb","lbm",IF(F3="----","F",F3))))))) -> g
A4: Flour | B4: 3 | C4: tbsp | D4: =IF(C4="oz","ozm",IF(C4="tbsp","tbs",IF(C4="fl oz","oz",IF(C4="L","l",IF(C4="mL","ml",IF(C4="lb","lbm",IF(C4="----","F",C4))))))) -> tbs | E4: =IF(AND(D4="F",G4="F"),B4,CONVERT(B4,D4,G4))*'La''tine - Sample Recipe'!$C$3/'La''tine - Sample Recipe'!$B$3 -> 1.59 | F4: tbsp | G4: =IF(F4="oz","ozm",IF(F4="tbsp","tbs",IF(F4="fl oz","oz",IF(F4="L","l",IF(F4="mL","ml",IF(F4="lb","lbm",IF(F4="----","F",F4))))))) -> tbs
A5: Onion | B5: 250 | C5: g | D5: =IF(C5="oz","ozm",IF(C5="tbsp","tbs",IF(C5="fl oz","oz",IF(C5="L","l",IF(C5="mL","ml",IF(C5="lb","lbm",IF(C5="----","F",C5))))))) -> g | E5: =IF(AND(D5="F",G5="F"),B5,CONVERT(B5,D5,G5))*'La''tine - Sample Recipe'!$C$3/'La''tine - Sample Recipe'!$B$3 -> 132.5 | F5: g | G5: =IF(F5="oz","ozm",IF(F5="tbsp","tbs",IF(F5="fl oz","oz",IF(F5="L","l",IF(F5="mL","ml",IF(F5="lb","lbm",IF(F5="----","F",F5))))))) -> g
A6: Spinach | B6: 0.75 | C6: kg | D6: =IF(C6="oz","ozm",IF(C6="tbsp","tbs",IF(C6="fl oz","oz",IF(C6="L","l",IF(C6="mL","ml",IF(C6="lb","lbm",IF(C6="----","F",C6))))))) -> kg | E6: =IF(AND(D6="F",G6="F"),B6,CONVERT(B6,D6,G6))*'La''tine - Sample Recipe'!$C$3/'La''tine - Sample Recipe'!$B$3 -> 0.3975 | F6: kg | G6: =IF(F6="oz","ozm",IF(F6="tbsp","tbs",IF(F6="fl oz","oz",IF(F6="L","l",IF(F6="mL","ml",IF(F6="lb","lbm",IF(F6="----","F",F6))))))) -> kg
A7: Olive Oil | B7: 120 | C7: mL | D7: =IF(C7="oz","ozm",IF(C7="tbsp","tbs",IF(C7="fl oz","oz",IF(C7="L","l",IF(C7="mL","ml",IF(C7="lb","lbm",IF(C7="----","F",C7))))))) -> ml | E7: =IF(AND(D7="F",G7="F"),B7,CONVERT(B7,D7,G7))*'La''tine - Sample Recipe'!$C$3/'La''tine - Sample Recipe'!$B$3 -> 63.6 | F7: mL | G7: =IF(F7="oz","ozm",IF(F7="tbsp","tbs",IF(F7="fl oz","oz",IF(F7="L","l",IF(F7="mL","ml",IF(F7="lb","lbm",IF(F7="----","F",F7))))))) -> ml
A8: Pomegranate Molasse | B8: 2 | C8: tbsp | D8: =IF(C8="oz","ozm",IF(C8="tbsp","tbs",IF(C8="fl oz","oz",IF(C8="L","l",IF(C8="mL","ml",IF(C8="lb","lbm",IF(C8="----","F",C8))))))) -> tbs | E8: =IF(AND(D8="F",G8="F"),B8,CONVERT(B8,D8,G8))*'La''tine - Sample Recipe'!$C$3/'La''tine - Sample Recipe'!$B$3 -> 1.06 | F8: tbsp | G8: =IF(F8="oz","ozm",IF(F8="tbsp","tbs",IF(F8="fl oz","oz",IF(F8="L","l",IF(F8="mL","ml",IF(F8="lb","lbm",IF(F8="----","F",F8))))))) -> tbs
A9: Pomegranate | B9: 50 | C9: g | D9: =IF(C9="oz","ozm",IF(C9="tbsp","tbs",IF(C9="fl oz","oz",IF(C9="L","l",IF(C9="mL","ml",IF(C9="lb","lbm",IF(C9="----","F",C9))))))) -> g | E9: 25 | F9: g | G9: =IF(F9="oz","ozm",IF(F9="tbsp","tbs",IF(F9="fl oz","oz",IF(F9="L","l",IF(F9="mL","ml",IF(F9="lb","lbm",IF(F9="----","F",F9))))))) -> g
A10: Summac | B10: 1.5 | C10: tbsp | D10: =IF(C10="oz","ozm",IF(C10="tbsp","tbs",IF(C10="fl oz","oz",IF(C10="L","l",IF(C10="mL","ml",IF(C10="lb","lbm",IF(C10="----","F",C10))))))) -> tbs | E10: =IF(AND(D10="F",G10="F"),B10,CONVERT(B10,D10,G10))*'La''tine - Sample Recipe'!$C$3/'La''tine - Sample Recipe'!$B$3 -> 0.795 | F10: tbsp | G10: =IF(F10="oz","ozm",IF(F10="tbsp","tbs",IF(F10="fl oz","oz",IF(F10="L","l",IF(F10="mL","ml",IF(F10="lb","lbm",IF(F10="----","F",F10))))))) -> tbs
A11: Lemon Zest | B11: 5 | C11: g | D11: =IF(C11="oz","ozm",IF(C11="tbsp","tbs",IF(C11="fl oz","oz",IF(C11="L","l",IF(C11="mL","ml",IF(C11="lb","lbm",IF(C11="----","F",C11))))))) -> g | E11: =IF(AND(D11="F",G11="F"),B11,CONVERT(B11,D11,G11))*'La''tine - Sample Recipe'!$C$3/'La''tine - Sample Recipe'!$B$3 -> 2.65 | F11: g | G11: =IF(F11="oz","ozm",IF(F11="tbsp","tbs",IF(F11="fl oz","oz",IF(F11="L","l",IF(F11="mL","ml",IF(F11="lb","lbm",IF(F11="----","F",F11))))))) -> g
A12: Cumin | B12: 1 | C12: tsp | D12: =IF(C12="oz","ozm",IF(C12="tbsp","tbs",IF(C12="fl oz","oz",IF(C12="L","l",IF(C12="mL","ml",IF(C12="lb","lbm",IF(C12="----","F",C12))))))) -> tsp | E12: =IF(AND(D12="F",G12="F"),B12,CONVERT(B12,D12,G12))*'La''tine - Sample Recipe'!$C$3/'La''tine - Sample Recipe'!$B$3 -> 0.53 | F12: tsp | G12: =IF(F12="oz","ozm",IF(F12="tbsp","tbs",IF(F12="fl oz","oz",IF(F12="L","l",IF(F12="mL","ml",IF(F12="lb","lbm",IF(F12="----","F",F12))))))) -> tsp
A13: White Pepper | B13: 1 | C13: tsp | D13: =IF(C13="oz","ozm",IF(C13="tbsp","tbs",IF(C13="fl oz","oz",IF(C13="L","l",IF(C13="mL","ml",IF(C13="lb","lbm",IF(C13="----","F",C13))))))) -> tsp | E13: =IF(AND(D13="F",G13="F"),B13,CONVERT(B13,D13,G13))*'La''tine - Sample Recipe'!$C$3/'La''tine - Sample Recipe'!$B$3 -> 0.53 | F13: tsp | G13: =IF(F13="oz","ozm",IF(F13="tbsp","tbs",IF(F13="fl oz","oz",IF(F13="L","l",IF(F13="mL","ml",IF(F13="lb","lbm",IF(F13="----","F",F13))))))) -> tsp
A14: Cumin | B14: 1 | C14: tsp | D14: =IF(C14="oz","ozm",IF(C14="tbsp","tbs",IF(C14="fl oz","oz",IF(C14="L","l",IF(C14="mL","ml",IF(C14="lb","lbm",IF(C14="----","F",C14))))))) -> tsp | E14: =IF(AND(D14="F",G14="F"),B14,CONVERT(B14,D14,G14))*'La''tine - Sample Recipe'!$C$3/'La''tine - Sample Recipe'!$B$3 -> 0.53 | F14: tsp | G14: =IF(F14="oz","ozm",IF(F14="tbsp","tbs",IF(F14="fl oz","oz",IF(F14="L","l",IF(F14="mL","ml",IF(F14="lb","lbm",IF(F14="----","F",F14))))))) -> tsp
A15: Salt | B15: 1 | C15: tbsp | D15: =IF(C15="oz","ozm",IF(C15="tbsp","tbs",IF(C15="fl oz","oz",IF(C15="L","l",IF(C15="mL","ml",IF(C15="lb","lbm",IF(C15="----","F",C15))))))) -> tbs | E15: =IF(AND(D15="F",G15="F"),B15,CONVERT(B15,D15,G15))*'La''tine - Sample Recipe'!$C$3/'La''tine - Sample Recipe'!$B$3 -> 1.59 | F15: tsp | G15: =IF(F15="oz","ozm",IF(F15="tbsp","tbs",IF(F15="fl oz","oz",IF(F15="L","l",IF(F15="mL","ml",IF(F15="lb","lbm",IF(F15="----","F",F15))))))) -> tsp
A16: Ground Pepper | B16: 0.5 | C16: tbsp | D16: =IF(C16="oz","ozm",IF(C16="tbsp","tbs",IF(C16="fl oz","oz",IF(C16="L","l",IF(C16="mL","ml",IF(C16="lb","lbm",IF(C16="----","F",C16))))))) -> tbs | E16: 0.25 | F16: tbsp | G16: =IF(F16="oz","ozm",IF(F16="tbsp","tbs",IF(F16="fl oz","oz",IF(F16="L","l",IF(F16="mL","ml",IF(F16="lb","lbm",IF(F16="----","F",F16))))))) -> tbs
D17: =IF(C17="oz","ozm",IF(C17="tbsp","tbs",IF(C17="fl oz","oz",IF(C17="L","l",IF(C17="mL","ml",IF(C17="lb","lbm",IF(C17="----","F",C17))))))) | G17: =IF(F17="oz","ozm",IF(F17="tbsp","tbs",IF(F17="fl oz","oz",IF(F17="L","l",IF(F17="mL","ml",IF(F17="lb","lbm",IF(F17="----","F",F17)))))))

Sheet La'tine - Drawings

Sheet Spiced Butter E'rass - Sample R
A1: Sample Recipe
B2: Recipe serves | C2: Prepared for
B3: 10 | C3: 5.3

Sheet Spiced Butter E'rass - Recipe
A1: Ingredient | B1: Regular
A2: Meat | B2: 35 | C2: g | D2: =IF(C2="oz","ozm",IF(C2="tbsp","tbs",IF(C2="fl oz","oz",IF(C2="L","l",IF(C2="mL","ml",IF(C2="lb","lbm",IF(C2="----","F",C2))))))) -> g | G2: =IF(F2="oz","ozm",IF(F2="tbsp","tbs",IF(F2="fl oz","oz",IF(F2="L","l",IF(F2="mL","ml",IF(F2="lb","lbm",IF(F2="----","F",F2)))))))
A3: Borghol | B3: 20 | C3: g | D3: =IF(C3="oz","ozm",IF(C3="tbsp","tbs",IF(C3="fl oz","oz",IF(C3="L","l",IF(C3="mL","ml",IF(C3="lb","lbm",IF(C3="----","F",C3))))))) -> g | G3: =IF(F3="oz","ozm",IF(F3="tbsp","tbs",IF(F3="fl oz","oz",IF(F3="L","l",IF(F3="mL","ml",IF(F3="lb","lbm",IF(F3="----","F",F3)))))))
A4: Butter | B4: 15 | C4: g | D4: =IF(C4="oz","ozm",IF(C4="tbsp","tbs",IF(C4="fl oz","oz",IF(C4="L","l",IF(C4="mL","ml",IF(C4="lb","lbm",IF(C4="----","F",C4))))))) -> g | G4: =IF(F4="oz","ozm",IF(F4="tbsp","tbs",IF(F4="fl oz","oz",IF(F4="L","l",IF(F4="mL","ml",IF(F4="lb","lbm",IF(F4="----","F",F4)))))))
A5: Onion | B5: 5 | C5: g | D5: =IF(C5="oz","ozm",IF(C5="tbsp","tbs",IF(C5="fl oz","oz",IF(C5="L","l",IF(C5="mL","ml",IF(C5="lb","lbm",IF(C5="----","F",C5))))))) -> g | G5: =IF(F5="oz","ozm",IF(F5="tbsp","tbs",IF(F5="fl oz","oz",IF(F5="L","l",IF(F5="mL","ml",IF(F5="lb","lbm",IF(F5="----","F",F5)))))))
A6: Red Pepper | B6: Pinch | D6: =IF(C6="oz","ozm",IF(C6="tbsp","tbs",IF(C6="fl oz","oz",IF(C6="L","l",IF(C6="mL","ml",IF(C6="lb","lbm",IF(C6="----","F",C6))))))) | G6: =IF(F6="oz","ozm",IF(F6="tbsp","tbs",IF(F6="fl oz","oz",IF(F6="L","l",IF(F6="mL","ml",IF(F6="lb","lbm",IF(F6="----","F",F6)))))))
A7: Salt | B7: Pinch | D7: =IF(C7="oz","ozm",IF(C7="tbsp","tbs",IF(C7="fl oz","oz",IF(C7="L","l",IF(C7="mL","ml",IF(C7="lb","lbm",IF(C7="----","F",C7))))))) | G7: =IF(F7="oz","ozm",IF(F7="tbsp","tbs",IF(F7="fl oz","oz",IF(F7="L","l",IF(F7="mL","ml",IF(F7="lb","lbm",IF(F7="----","F",F7))))))) -> 0
A8: Ground Pepper | B8: Pinch | D8: =IF(C8="oz","ozm",IF(C8="tbsp","tbs",IF(C8="fl oz","oz",IF(C8="L","l",IF(C8="mL","ml",IF(C8="lb","lbm",IF(C8="----","F",C8))))))) | G8: =IF(F8="oz","ozm",IF(F8="tbsp","tbs",IF(F8="fl oz","oz",IF(F8="L","l",IF(F8="mL","ml",IF(F8="lb","lbm",IF(F8="----","F",F8)))))))
A9: Dried Mind | B9: Pinch | D9: =IF(C9="oz","ozm",IF(C9="tbsp","tbs",IF(C9="fl oz","oz",IF(C9="L","l",IF(C9="mL","ml",IF(C9="lb","lbm",IF(C9="----","F",C9))))))) | G9: =IF(F9="oz","ozm",IF(F9="tbsp","tbs",IF(F9="fl oz","oz",IF(F9="L","l",IF(F9="mL","ml",IF(F9="lb","lbm",IF(F9="----","F",F9)))))))

Sheet Spiced Butter E'rass - Drawings

Sheet Kabkoub Acovado - Sample Recipe
A1: Sample Recipe
B2: Recipe serves | C2: Prepared for
B3: 10 | C3: 0

Sheet Kabkoub Acovado - Recipe
A1: Ingredient | B1: Regular | E1: Small
A2: Labneh | B2: 30 | C2: g | D2: =IF(C2="oz","ozm",IF(C2="tbsp","tbs",IF(C2="fl oz","oz",IF(C2="L","l",IF(C2="mL","ml",IF(C2="lb","lbm",IF(C2="----","F",C2))))))) -> g | E2: =IF(AND(D2="F",G2="F"),B2,CONVERT(B2,D2,G2))*'Kabkoub Acovado - Sample Recipe'!$C$3/'Kabkoub Acovado - Sample Recipe'!$B$3 -> 0 | F2: g | G2: =IF(F2="oz","ozm",IF(F2="tbsp","tbs",IF(F2="fl oz","oz",IF(F2="L","l",IF(F2="mL","ml",IF(F2="lb","lbm",IF(F2="----","F",F2))))))) -> g
A3: Avocado | B3: 30 | C3: g | D3: =IF(C3="oz","ozm",IF(C3="tbsp","tbs",IF(C3="fl oz","oz",IF(C3="L","l",IF(C3="mL","ml",IF(C3="lb","lbm",IF(C3="----","F",C3))))))) -> g | E3: =IF(AND(D3="F",G3="F"),B3,CONVERT(B3,D3,G3))*'Kabkoub Acovado - Sample Recipe'!$C$3/'Kabkoub Acovado - Sample Recipe'!$B$3 -> 0 | F3: g | G3: =IF(F3="oz","ozm",IF(F3="tbsp","tbs",IF(F3="fl oz","oz",IF(F3="L","l",IF(F3="mL","ml",IF(F3="lb","lbm",IF(F3="----","F",F3))))))) -> g
A4: Lemon Juice | B4: 1 | C4: tsp | D4: =IF(C4="oz","ozm",IF(C4="tbsp","tbs",IF(C4="fl oz","oz",IF(C4="L","l",IF(C4="mL","ml",IF(C4="lb","lbm",IF(C4="----","F",C4))))))) -> tsp | E4: =IF(AND(D4="F",G4="F"),B4,CONVERT(B4,D4,G4))*'Kabkoub Acovado - Sample Recipe'!$C$3/'Kabkoub Acovado - Sample Recipe'!$B$3 -> 0 | F4: tbsp | G4: =IF(F4="oz","ozm",IF(F4="tbsp","tbs",IF(F4="fl oz","oz",IF(F4="L","l",IF(F4="mL","ml",IF(F4="lb","lbm",IF(F4="----","F",F4))))))) -> tbs
A5: White Pepper | B5: Pinch | D5: =IF(C5="oz","ozm",IF(C5="tbsp","tbs",IF(C5="fl oz","oz",IF(C5="L","l",IF(C5="mL","ml",IF(C5="lb","lbm",IF(C5="----","F",C5))))))) | G5: =IF(F5="oz","ozm",IF(F5="tbsp","tbs",IF(F5="fl oz","oz",IF(F5="L","l",IF(F5="mL","ml",IF(F5="lb","lbm",IF(F5="----","F",F5))))))) -> 0

Sheet Kabkoub Acovado - Drawings

Sheet Kabkoub Feta - Sample Recipe
A1: Sample Recipe
B2: Recipe serves | C2: Prepared for
B3: 10 | C3: 0

Sheet Kabkoub Feta - Recipe
A1: Ingredient | B1: Regular | E1: Small
A2: Feta | B2: 60 | C2: g | D2: =IF(C2="oz","ozm",IF(C2="tbsp","tbs",IF(C2="fl oz","oz",IF(C2="L","l",IF(C2="mL","ml",IF(C2="lb","lbm",IF(C2="----","F",C2))))))) -> g | E2: =IF(AND(D2="F",G2="F"),B2,CONVERT(B2,D2,G2))*'Kabkoub Feta - Sample Recipe'!$C$3/'Kabkoub Feta - Sample Recipe'!$B$3 -> 0 | F2: g | G2: =IF(F2="oz","ozm",IF(F2="tbsp","tbs",IF(F2="fl oz","oz",IF(F2="L","l",IF(F2="mL","ml",IF(F2="lb","lbm",IF(F2="----","F",F2))))))) -> g
A3: Onion | B3: 8 | C3: g | D3: =IF(C3="oz","ozm",IF(C3="tbsp","tbs",IF(C3="fl oz","oz",IF(C3="L","l",IF(C3="mL","ml",IF(C3="lb","lbm",IF(C3="----","F",C3))))))) -> g | E3: =IF(AND(D3="F",G3="F"),B3,CONVERT(B3,D3,G3))*'Kabkoub Feta - Sample Recipe'!$C$3/'Kabkoub Feta - Sample Recipe'!$B$3 -> 0 | F3: g | G3: =IF(F3="oz","ozm",IF(F3="tbsp","tbs",IF(F3="fl oz","oz",IF(F3="L","l",IF(F3="mL","ml",IF(F3="lb","lbm",IF(F3="----","F",F3))))))) -> g
A4: Oregano | B4: Pinch | D4: =IF(C4="oz","ozm",IF(C4="tbsp","tbs",IF(C4="fl oz","oz",IF(C4="L","l",IF(C4="mL","ml",IF(C4="lb","lbm",IF(C4="----","F",C4))))))) | G4: =IF(F4="oz","ozm",IF(F4="tbsp","tbs",IF(F4="fl oz","oz",IF(F4="L","l",IF(F4="mL","ml",IF(F4="lb","lbm",IF(F4="----","F",F4))))))) -> 0
A5: White Pepper | B5: Pinch | D5: =IF(C5="oz","ozm",IF(C5="tbsp","tbs",IF(C5="fl oz","oz",IF(C5="L","l",IF(C5="mL","ml",IF(C5="lb","lbm",IF(C5="----","F",C5))))))) | G5: =IF(F5="oz","ozm",IF(F5="tbsp","tbs",IF(F5="fl oz","oz",IF(F5="L","l",IF(F5="mL","ml",IF(F5="lb","lbm",IF(F5="----","F",F5))))))) -> 0
A6: Walsnuts | B6: 3g | D6: =IF(C6="oz","ozm",IF(C6="tbsp","tbs",IF(C6="fl oz","oz",IF(C6="L","l",IF(C6="mL","ml",IF(C6="lb","lbm",IF(C6="----","F",C6))))))) | G6: =IF(F6="oz","ozm",IF(F6="tbsp","tbs",IF(F6="fl oz","oz",IF(F6="L","l",IF(F6="mL","ml",IF(F6="lb","lbm",IF(F6="----","F",F6)))))))

Sheet Kabkoub Feta - Drawings

Sheet Kabkoub Onion - Sample Recipe
A1: Sample Recipe
B2: Recipe serves | C2: Prepared for
B3: 10 | C3: 0

Sheet Kabkoub Onion - Recipe
A1: Ingredient | B1: Regular | E1: Small
A2: Dried Almonds | B2: 5 | C2: g | D2: =IF(C2="oz","ozm",IF(C2="tbsp","tbs",IF(C2="fl oz","oz",IF(C2="L","l",IF(C2="mL","ml",IF(C2="lb","lbm",IF(C2="----","F",C2))))))) -> g | E2: =IF(AND(D2="F",G2="F"),B2,CONVERT(B2,D2,G2))*'Kabkoub Onion - Sample Recipe'!$C$3/'Kabkoub Onion - Sample Recipe'!$B$3 -> 0 | F2: g | G2: =IF(F2="oz","ozm",IF(F2="tbsp","tbs",IF(F2="fl oz","oz",IF(F2="L","l",IF(F2="mL","ml",IF(F2="lb","lbm",IF(F2="----","F",F2))))))) -> g
A3: Onion | B3: 60 | C3: g | D3: =IF(C3="oz","ozm",IF(C3="tbsp","tbs",IF(C3="fl oz","oz",IF(C3="L","l",IF(C3="mL","ml",IF(C3="lb","lbm",IF(C3="----","F",C3))))))) -> g | E3: =IF(AND(D3="F",G3="F"),B3,CONVERT(B3,D3,G3))*'Kabkoub Onion - Sample Recipe'!$C$3/'Kabkoub Onion - Sample Recipe'!$B$3 -> 0 | F3: g | G3: =IF(F3="oz","ozm",IF(F3="tbsp","tbs",IF(F3="fl oz","oz",IF(F3="L","l",IF(F3="mL","ml",IF(F3="lb","lbm",IF(F3="----","F",F3))))))) -> g
A4: Black Pepper | B4: Pinch | D4: =IF(C4="oz","ozm",IF(C4="tbsp","tbs",IF(C4="fl oz","oz",IF(C4="L","l",IF(C4="mL","ml",IF(C4="lb","lbm",IF(C4="----","F",C4))))))) | G4: =IF(F4="oz","ozm",IF(F4="tbsp","tbs",IF(F4="fl oz","oz",IF(F4="L","l",IF(F4="mL","ml",IF(F4="lb","lbm",IF(F4="----","F",F4))))))) -> 0
A5: Pom. Molasses | B5: 1 | C5: tsp | D5: =IF(C5="oz","ozm",IF(C5="tbsp","tbs",IF(C5="fl oz","oz",IF(C5="L","l",IF(C5="mL","ml",IF(C5="lb","lbm",IF(C5="----","F",C5))))))) -> tsp | G5: =IF(F5="oz","ozm",IF(F5="tbsp","tbs",IF(F5="fl oz","oz",IF(F5="L","l",IF(F5="mL","ml",IF(F5="lb","lbm",IF(F5="----","F",F5))))))) -> 0

Sheet Kabkoub Onion - Drawings

Sheet Kabkoub Eggplant - Sample Recip
A1: Sample Recipe
B2: Recipe serves | C2: Prepared for
B3: 10 | C3: 0

Sheet Kabkoub Eggplant - Recipe
A1: Ingredient | B1: Regular | E1: Small
A2: Eggplant | B2: 60 | C2: g | D2: =IF(C2="oz","ozm",IF(C2="tbsp","tbs",IF(C2="fl oz","oz",IF(C2="L","l",IF(C2="mL","ml",IF(C2="lb","lbm",IF(C2="----","F",C2))))))) -> g | E2: =IF(AND(D2="F",G2="F"),B2,CONVERT(B2,D2,G2))*'Kabkoub Eggplant - Sample Recip'!$C$3/'Kabkoub Eggplant - Sample Recip'!$B$3 -> 0 | F2: g | G2: =IF(F2="oz","ozm",IF(F2="tbsp","tbs",IF(F2="fl oz","oz",IF(F2="L","l",IF(F2="mL","ml",IF(F2="lb","lbm",IF(F2="----","F",F2))))))) -> g
A3: Pomegrante | B3: 5 | C3: g | D3: =IF(C3="oz","ozm",IF(C3="tbsp","tbs",IF(C3="fl oz","oz",IF(C3="L","l",IF(C3="mL","ml",IF(C3="lb","lbm",IF(C3="----","F",C3))))))) -> g | E3: =IF(AND(D3="F",G3="F"),B3,CONVERT(B3,D3,G3))*'Kabkoub Eggplant - Sample Recip'!$C$3/'Kabkoub Eggplant - Sample Recip'!$B$3 -> 0 | F3: g | G3: =IF(F3="oz","ozm",IF(F3="tbsp","tbs",IF(F3="fl oz","oz",IF(F3="L","l",IF(F3="mL","ml",IF(F3="lb","lbm",IF(F3="----","F",F3))))))) -> g
A4: Dried Mint | B4: Pinch | D4: =IF(C4="oz","ozm",IF(C4="tbsp","tbs",IF(C4="fl oz","oz",IF(C4="L","l",IF(C4="mL","ml",IF(C4="lb","lbm",IF(C4="----","F",C4))))))) | G4: =IF(F4="oz","ozm",IF(F4="tbsp","tbs",IF(F4="fl oz","oz",IF(F4="L","l",IF(F4="mL","ml",IF(F4="lb","lbm",IF(F4="----","F",F4))))))) -> 0
A5: Pom. Molasses | B5: 1 | C5: tsp | D5: =IF(C5="oz","ozm",IF(C5="tbsp","tbs",IF(C5="fl oz","oz",IF(C5="L","l",IF(C5="mL","ml",IF(C5="lb","lbm",IF(C5="----","F",C5))))))) -> tsp | G5: =IF(F5="oz","ozm",IF(F5="tbsp","tbs",IF(F5="fl oz","oz",IF(F5="L","l",IF(F5="mL","ml",IF(F5="lb","lbm",IF(F5="----","F",F5))))))) -> 0

Sheet Kabkoub Eggplant - Drawings

Sheet Meat Kabkoub - Sample Recipe
A1: Sample Recipe
B2: Recipe serves | C2: Prepared for
B3: 10 | C3: 0

Sheet Meat Kabkoub - Recipe
A1: Ingredient | B1: Regular | E1: Small
A2: Minced Meat | B2: 60 | C2: g | D2: =IF(C2="oz","ozm",IF(C2="tbsp","tbs",IF(C2="fl oz","oz",IF(C2="L","l",IF(C2="mL","ml",IF(C2="lb","lbm",IF(C2="----","F",C2))))))) -> g | E2: =IF(AND(D2="F",G2="F"),B2,CONVERT(B2,D2,G2))*'Meat Kabkoub - Sample Recipe'!$C$3/'Meat Kabkoub - Sample Recipe'!$B$3 -> 0 | F2: g | G2: =IF(F2="oz","ozm",IF(F2="tbsp","tbs",IF(F2="fl oz","oz",IF(F2="L","l",IF(F2="mL","ml",IF(F2="lb","lbm",IF(F2="----","F",F2))))))) -> g
A3: Pine Nuts | B3: 2 | C3: g | D3: =IF(C3="oz","ozm",IF(C3="tbsp","tbs",IF(C3="fl oz","oz",IF(C3="L","l",IF(C3="mL","ml",IF(C3="lb","lbm",IF(C3="----","F",C3))))))) -> g | E3: =IF(AND(D3="F",G3="F"),B3,CONVERT(B3,D3,G3))*'Meat Kabkoub - Sample Recipe'!$C$3/'Meat Kabkoub - Sample Recipe'!$B$3 -> 0 | F3: g | G3: =IF(F3="oz","ozm",IF(F3="tbsp","tbs",IF(F3="fl oz","oz",IF(F3="L","l",IF(F3="mL","ml",IF(F3="lb","lbm",IF(F3="----","F",F3))))))) -> g
A4: Onion | B4: 5 | C4: g | D4: =IF(C4="oz","ozm",IF(C4="tbsp","tbs",IF(C4="fl oz","oz",IF(C4="L","l",IF(C4="mL","ml",IF(C4="lb","lbm",IF(C4="----","F",C4))))))) -> g | G4: =IF(F4="oz","ozm",IF(F4="tbsp","tbs",IF(F4="fl oz","oz",IF(F4="L","l",IF(F4="mL","ml",IF(F4="lb","lbm",IF(F4="----","F",F4))))))) -> 0
A5: Pom. Molasses | B5: 0.5 | C5: tsp | D5: =IF(C5="oz","ozm",IF(C5="tbsp","tbs",IF(C5="fl oz","oz",IF(C5="L","l",IF(C5="mL","ml",IF(C5="lb","lbm",IF(C5="----","F",C5))))))) -> tsp | G5: =IF(F5="oz","ozm",IF(F5="tbsp","tbs",IF(F5="fl oz","oz",IF(F5="L","l",IF(F5="mL","ml",IF(F5="lb","lbm",IF(F5="----","F",F5))))))) -> 0
A6: Pinch Salt | D6: =IF(C6="oz","ozm",IF(C6="tbsp","tbs",IF(C6="fl oz","oz",IF(C6="L","l",IF(C6="mL","ml",IF(C6="lb","lbm",IF(C6="----","F",C6))))))) | G6: =IF(F6="oz","ozm",IF(F6="tbsp","tbs",IF(F6="fl oz","oz",IF(F6="L","l",IF(F6="mL","ml",IF(F6="lb","lbm",IF(F6="----","F",F6)))))))
A7: Pinch Ground Pepper | D7: =IF(C7="oz","ozm",IF(C7="tbsp","tbs",IF(C7="fl oz","oz",IF(C7="L","l",IF(C7="mL","ml",IF(C7="lb","lbm",IF(C7="----","F",C7))))))) | G7: =IF(F7="oz","ozm",IF(F7="tbsp","tbs",IF(F7="fl oz","oz",IF(F7="L","l",IF(F7="mL","ml",IF(F7="lb","lbm",IF(F7="----","F",F7)))))))
A8: Butter | B8: 0.25 | C8: tsp | D8: =IF(C8="oz","ozm",IF(C8="tbsp","tbs",IF(C8="fl oz","oz",IF(C8="L","l",IF(C8="mL","ml",IF(C8="lb","lbm",IF(C8="----","F",C8))))))) -> tsp | G8: =IF(F8="oz","ozm",IF(F8="tbsp","tbs",IF(F8="fl oz","oz",IF(F8="L","l",IF(F8="mL","ml",IF(F8="lb","lbm",IF(F8="----","F",F8))))))) -> 0

Sheet Meat Kabkoub - Drawings

Sheet Tzatziki Kabkoub - Sample Recip
A1: Sample Recipe
B2: Recipe serves | C2: Prepared for
B3: 10 | C3: 0

Sheet Tzatziki Kabkoub - Recipe
A1: Ingredient | B1: Regular | E1: Small
A2: Tzatziki Sauce | B2: 60 | C2: g | D2: =IF(C2="oz","ozm",IF(C2="tbsp","tbs",IF(C2="fl oz","oz",IF(C2="L","l",IF(C2="mL","ml",IF(C2="lb","lbm",IF(C2="----","F",C2))))))) -> g | E2: =IF(AND(D2="F",G2="F"),B2,CONVERT(B2,D2,G2))*'Tzatziki Kabkoub - Sample Recip'!$C$3/'Tzatziki Kabkoub - Sample Recip'!$B$3 -> 0 | F2: g | G2: =IF(F2="oz","ozm",IF(F2="tbsp","tbs",IF(F2="fl oz","oz",IF(F2="L","l",IF(F2="mL","ml",IF(F2="lb","lbm",IF(F2="----","F",F2))))))) -> g

Sheet Tzatziki Kabkoub - Drawings

Sheet Vegan Tartelettes - Recipe
A1: Ingredient | B1: Regular | E1: Small
A2: Hommos | B2: 20 | C2: g | D2: =IF(C2="oz","ozm",IF(C2="tbsp","tbs",IF(C2="fl oz","oz",IF(C2="L","l",IF(C2="mL","ml",IF(C2="lb","lbm",IF(C2="----","F",C2))))))) -> g | F2: g | G2: =IF(F2="oz","ozm",IF(F2="tbsp","tbs",IF(F2="fl oz","oz",IF(F2="L","l",IF(F2="mL","ml",IF(F2="lb","lbm",IF(F2="----","F",F2))))))) -> g
A3: Borghol | B3: 20 | C3: g | F3: g
A4: Flour | B4: 15 | C4: g | F4: g
A5: Onion | B5: 8 | C5: g | F5: tsp
A6: Salt | C6: Pinch | F6: tsp
A7: White Pepper | C7: Pinch | F7: tsp
A8: Dried Mint | C8: Pinch | F8: tsp

Sheet Vegan Tartelettes - Recipe-1
A1: Ingredient | B1: Regular | E1: Small
A2: Tahini Sauce | B2: 20 | C2: g | D2: =IF(C2="oz","ozm",IF(C2="tbsp","tbs",IF(C2="fl oz","oz",IF(C2="L","l",IF(C2="mL","ml",IF(C2="lb","lbm",IF(C2="----","F",C2))))))) -> g | G2: =IF(F2="oz","ozm",IF(F2="tbsp","tbs",IF(F2="fl oz","oz",IF(F2="L","l",IF(F2="mL","ml",IF(F2="lb","lbm",IF(F2="----","F",F2)))))))
A3: Borghol | B3: 20 | C3: g
A4: Flour | B4: 15 | C4: g
A5: Onion | B5: 8 | C5: g
A6: Salt | C6: Pinch
A7: White Pepper | C7: Pinch
A8: Dried Mint | C8: Pinch

Sheet Vegan Tartelettes - Drawings

Sheet Other - Outsourced
